hi
True
torch diagonostics
2.5.1
12.4
True
start to load light curves
loaded files
finished loading lcs
10
Beginning training...
Traceback (most recent call last):
  File "/home/pdong/.conda/envs/myenv/lib/python3.11/site-packages/pandas/core/indexes/base.py", line 3805, in get_loc
    return self._engine.get_loc(casted_key)
           ^^^^^^^^^^^^^^^^^^^^^^^^^^^^^^^^
  File "index.pyx", line 167, in pandas._libs.index.IndexEngine.get_loc
  File "index.pyx", line 196, in pandas._libs.index.IndexEngine.get_loc
  File "pandas/_libs/hashtable_class_helper.pxi", line 7081, in pandas._libs.hashtable.PyObjectHashTable.get_item
  File "pandas/_libs/hashtable_class_helper.pxi", line 7089, in pandas._libs.hashtable.PyObjectHashTable.get_item
KeyError: 0

The above exception was the direct cause of the following exception:

Traceback (most recent call last):
  File "/orcd/home/002/pdong/Astro UROP/big_model_bands.py", line 339, in <module>
    for batch in train_loader:
  File "/home/pdong/.conda/envs/myenv/lib/python3.11/site-packages/torch/utils/data/dataloader.py", line 701, in __next__
    data = self._next_data()
           ^^^^^^^^^^^^^^^^^
  File "/home/pdong/.conda/envs/myenv/lib/python3.11/site-packages/torch/utils/data/dataloader.py", line 757, in _next_data
    data = self._dataset_fetcher.fetch(index)  # may raise StopIteration
           ^^^^^^^^^^^^^^^^^^^^^^^^^^^^^^^^^^
  File "/home/pdong/.conda/envs/myenv/lib/python3.11/site-packages/torch/utils/data/_utils/fetch.py", line 55, in fetch
    return self.collate_fn(data)
           ^^^^^^^^^^^^^^^^^^^^^
  File "/orcd/home/002/pdong/Astro UROP/big_model_bands.py", line 291, in collate_fn_err_mult
    rate_low = [torch.tensor(lc[0]['RATE'].values.byteswap().newbyteorder(), dtype=torch.float32) for lc in batch]
               ^^^^^^^^^^^^^^^^^^^^^^^^^^^^^^^^^^^^^^^^^^^^^^^^^^^^^^^^^^^^^^^^^^^^^^^^^^^^^^^^^^^^^^^^^^^^^^^^^^^
  File "/orcd/home/002/pdong/Astro UROP/big_model_bands.py", line 291, in <listcomp>
    rate_low = [torch.tensor(lc[0]['RATE'].values.byteswap().newbyteorder(), dtype=torch.float32) for lc in batch]
                             ~~^^^
  File "/home/pdong/.conda/envs/myenv/lib/python3.11/site-packages/pandas/core/frame.py", line 4102, in __getitem__
    indexer = self.columns.get_loc(key)
              ^^^^^^^^^^^^^^^^^^^^^^^^^
  File "/home/pdong/.conda/envs/myenv/lib/python3.11/site-packages/pandas/core/indexes/base.py", line 3812, in get_loc
    raise KeyError(key) from err
KeyError: 0
